Workbook

Sheet 2026
A1: Column1 | B1: player | C1: team | D1: age | E1: season | F1: bust | G1: rotation | H1: starter | I1: all star | J1: all nba | K1: mvp | L1: 5th | M1: median | N1: 95th | O1: consensus
A2: 2301 | B2: Cameron Boozer | C2: Duke | D2: 19.30411 | E2: 2026 | F2: 0.001 | G2: 0.045 | H2: 0.207 | I2: 0.294 | J2: 0.399 | K2: 0.053 | L2: 0.03 | M2: 1.83 | N2: 4.55 | O2: =IF(_xlfn.XLOOKUP(Table323[[#This Row],[player]],consensus!A:A,consensus!A:A,0,0)<>0,1,0) -> 1
A3: 2071 | B3: Darryn Peterson | C3: Kansas | D3: 19.80274 | E3: 2026 | F3: 0.059 | G3: 0.212 | H3: 0.257 | I3: 0.215 | J3: 0.226 | K3: 0.031 | L3: -1.06 | M3: 0.88 | N3: 4.03 | O3: =IF(_xlfn.XLOOKUP(Table323[[#This Row],[player]],consensus!A:A,consensus!A:A,0,0)<>0,1,0) -> 1
A4: 2187 | B4: Keaton Wagler | C4: Illinois | D4: 20.060274 | E4: 2026 | F4: 0.009 | G4: 0.206 | H4: 0.334 | I4: 0.244 | J4: 0.197 | K4: 0.011 | L4: -0.61 | M4: 0.84 | N4: 3.33 | O4: =IF(_xlfn.XLOOKUP(Table323[[#This Row],[player]],consensus!A:A,consensus!A:A,0,0)<>0,1,0) -> 1
A5: 1960 | B5: Caleb Wilson | C5: North Carolina | D5: 20.30411 | E5: 2026 | F5: 0.076 | G5: 0.202 | H5: 0.289 | I5: 0.229 | J5: 0.192 | K5: 0.013 | L5: -1.23 | M5: 0.77 | N5: 3.4 | O5: =IF(_xlfn.XLOOKUP(Table323[[#This Row],[player]],consensus!A:A,consensus!A:A,0,0)<>0,1,0) -> 1
A6: 2157 | B6: AJ Dybantsa | C6: BYU | D6: 19.769863 | E6: 2026 | F6: 0.003 | G6: 0.221 | H6: 0.352 | I6: 0.243 | J6: 0.173 | K6: 0.007 | L6: -0.58 | M6: 0.76 | N6: 3.15 | O6: =IF(_xlfn.XLOOKUP(Table323[[#This Row],[player]],consensus!A:A,consensus!A:A,0,0)<>0,1,0) -> 1
A7: 1510 | B7: Allen Graves | C7: Santa Clara | D7: 21.060274 | E7: 2026 | F7: 0.059 | G7: 0.25 | H7: 0.298 | I7: 0.211 | J7: 0.172 | K7: 0.011 | L7: -1.06 | M7: 0.62 | N7: 3.27 | O7: =IF(_xlfn.XLOOKUP(Table323[[#This Row],[player]],consensus!A:A,consensus!A:A,0,0)<>0,1,0) -> 0
A8: 2332 | B8: Hannes Steinbach | C8: Washington | D8: 20.517808 | E8: 2026 | F8: 0.156 | G8: 0.202 | H8: 0.236 | I8: 0.185 | J8: 0.192 | K8: 0.028 | L8: -1.87 | M8: 0.59 | N8: 3.89 | O8: =IF(_xlfn.XLOOKUP(Table323[[#This Row],[player]],consensus!A:A,consensus!A:A,0,0)<>0,1,0) -> 1
A9: 1981 | B9: Kingston Flemings | C9: Houston | D9: 19.841096 | E9: 2026 | F9: 0.01 | G9: 0.299 | H9: 0.379 | I9: 0.213 | J9: 0.098 | K9: 0.001 | L9: -0.74 | M9: 0.47 | N9: 2.48 | O9: =IF(_xlfn.XLOOKUP(Table323[[#This Row],[player]],consensus!A:A,consensus!A:A,0,0)<>0,1,0) -> 1
A10: 1952 | B10: Ivan Kharchenkov | C10: Arizona | D10: 20.128767 | E10: 2026 | F10: 0.136 | G10: 0.24 | H10: 0.259 | I10: 0.186 | J10: 0.165 | K10: 0.013 | L10: -1.58 | M10: 0.45 | N10: 3.37 | O10: =IF(_xlfn.XLOOKUP(Table323[[#This Row],[player]],consensus!A:A,consensus!A:A,0,0)<>0,1,0) -> 0
A11: 1950 | B11: Koa Peat | C11: Arizona | D11: 19.794521 | E11: 2026 | F11: 0.082 | G11: 0.301 | H11: 0.314 | I11: 0.187 | J11: 0.113 | K11: 0.003 | L11: -1.19 | M11: 0.35 | N11: 2.69 | O11: =IF(_xlfn.XLOOKUP(Table323[[#This Row],[player]],consensus!A:A,consensus!A:A,0,0)<>0,1,0) -> 1
A12: 1951 | B12: Brayden Burries | C12: Arizona | D12: 21.134247 | E12: 2026 | F12: 0.065 | G12: 0.33 | H12: 0.303 | I12: 0.182 | J12: 0.115 | K12: 0.004 | L12: -1.08 | M12: 0.31 | N12: 2.76 | O12: =IF(_xlfn.XLOOKUP(Table323[[#This Row],[player]],consensus!A:A,consensus!A:A,0,0)<>0,1,0) -> 1
A13: 2190 | B13: Massamba Diop | C13: Arizona St. | D13: 20.060274 | E13: 2026 | F13: 0.169 | G13: 0.27 | H13: 0.279 | I13: 0.177 | J13: 0.102 | K13: 0.003 | L13: -1.77 | M13: 0.2 | N13: 2.58 | O13: =IF(_xlfn.XLOOKUP(Table323[[#This Row],[player]],consensus!A:A,consensus!A:A,0,0)<>0,1,0) -> 0
... A892: 216 | B892: Malachi Smith | C892: Connecticut | D892: 24.00274 | E892: 2026 | F892: 1 | G892: 0 | H892: 0 | I892: 0 | J892: 0 | K892: 0 | L892: -3.93 | M892: -3.35 | N892: -2.63 | O892: =IF(_xlfn.XLOOKUP(Table323[[#This Row],[player]],consensus!A:A,consensus!A:A,0,0)<>0,1,0) -> 0
A893: 2493 | B893: Kirill Elatontsev | C893: Oklahoma | E893: 2026 | F893: 1 | G893: 0 | H893: 0 | I893: 0 | J893: 0 | K893: 0 | L893: -3.75 | M893: -3.35 | N893: -2.64 | O893: =IF(_xlfn.XLOOKUP(Table323[[#This Row],[player]],consensus!A:A,consensus!A:A,0,0)<>0,1,0) -> 0
A894: 296 | B894: Max Mackinnon | C894: LSU | D894: 23.079452 | E894: 2026 | F894: 1 | G894: 0 | H894: 0 | I894: 0 | J894: 0 | K894: 0 | L894: -3.74 | M894: -3.35 | N894: -2.65 | O894: =IF(_xlfn.XLOOKUP(Table323[[#This Row],[player]],consensus!A:A,consensus!A:A,0,0)<>0,1,0) -> 0
A895: 830 | B895: Vincent Delano | C895: Northern Colorado | D895: 22.060274 | E895: 2026 | F895: 1 | G895: 0 | H895: 0 | I895: 0 | J895: 0 | K895: 0 | L895: -3.77 | M895: -3.35 | N895: -2.67 | O895: =IF(_xlfn.XLOOKUP(Table323[[#This Row],[player]],consensus!A:A,consensus!A:A,0,0)<>0,1,0) -> 0
A896: 435 | B896: Frank Mitchell | C896: St. Bonaventure | D896: 24.063014 | E896: 2026 | F896: 1 | G896: 0 | H896: 0 | I896: 0 | J896: 0 | K896: 0 | L896: -3.74 | M896: -3.35 | N896: -2.68 | O896: =IF(_xlfn.XLOOKUP(Table323[[#This Row],[player]],consensus!A:A,consensus!A:A,0,0)<>0,1,0) -> 0
A897: 518 | B897: Langston Reynolds | C897: Minnesota | D897: 23.063014 | E897: 2026 | F897: 1 | G897: 0 | H897: 0 | I897: 0 | J897: 0 | K897: 0 | L897: -3.76 | M897: -3.35 | N897: -2.68 | O897: =IF(_xlfn.XLOOKUP(Table323[[#This Row],[player]],consensus!A:A,consensus!A:A,0,0)<>0,1,0) -> 0
A898: 212 | B898: Ramon Walker Jr. | C898: Houston | D898: 24.063014 | E898: 2026 | F898: 0.991 | G898: 0.009 | H898: 0 | I898: 0 | J898: 0 | K898: 0 | L898: -3.8 | M898: -3.36 | N898: -1.7 | O898: =IF(_xlfn.XLOOKUP(Table323[[#This Row],[player]],consensus!A:A,consensus!A:A,0,0)<>0,1,0) -> 0
A899: 8 | B899: Rashaun Agee | C899: Texas A&M | D899: 26.013699 | E899: 2026 | F899: 0.999 | G899: 0.001 | H899: 0 | I899: 0 | J899: 0 | K899: 0 | L899: -3.81 | M899: -3.36 | N899: -2.3 | O899: =IF(_xlfn.XLOOKUP(Table323[[#This Row],[player]],consensus!A:A,consensus!A:A,0,0)<>0,1,0) -> 0
A900: 224 | B900: Nate Johnson | C900: Kansas St. | D900: 24.063014 | E900: 2026 | F900: 0.999 | G900: 0.001 | H900: 0 | I900: 0 | J900: 0 | K900: 0 | L900: -3.76 | M900: -3.36 | N900: -2.3 | O900: =IF(_xlfn.XLOOKUP(Table323[[#This Row],[player]],consensus!A:A,consensus!A:A,0,0)<>0,1,0) -> 0
A901: 317 | B901: Grant Newell | C901: Western Kentucky | D901: 23.063014 | E901: 2026 | F901: 1 | G901: 0 | H901: 0 | I901: 0 | J901: 0 | K901: 0 | L901: -3.78 | M901: -3.36 | N901: -2.48 | O901: =IF(_xlfn.XLOOKUP(Table323[[#This Row],[player]],consensus!A:A,consensus!A:A,0,0)<>0,1,0) -> 0
A902: 879 | B902: Luke Wilson | C902: Appalachian St. | D902: 22.060274 | E902: 2026 | F902: 1 | G902: 0 | H902: 0 | I902: 0 | J902: 0 | K902: 0 | L902: -3.8 | M902: -3.36 | N902: -2.55 | O902: =IF(_xlfn.XLOOKUP(Table323[[#This Row],[player]],consensus!A:A,consensus!A:A,0,0)<>0,1,0) -> 0
A903: 2150 | B903: Joshua Lewis | C903: Louisiana | D903: 20.060274 | E903: 2026 | F903: 1 | G903: 0 | H903: 0 | I903: 0 | J903: 0 | K903: 0 | L903: -3.77 | M903: -3.36 | N903: -2.57 | O903: =IF(_xlfn.XLOOKUP(Table323[[#This Row],[player]],consensus!A:A,consensus!A:A,0,0)<>0,1,0) -> 0
A904: 1060 | B904: Terrance Dixon Jr. | C904: Southern | D904: 23.063014 | E904: 2026 | F904: 1 | G904: 0 | H904: 0 | I904: 0 | J904: 0 | K904: 0 | L904: -3.77 | M904: -3.36 | N904: -2.61 | O904: =IF(_xlfn.XLOOKUP(Table323[[#This Row],[player]],consensus!A:A,consensus!A:A,0,0)<>0,1,0) -> 0
A905: 1832 | B905: Jack Stanton | C905: Princeton | D905: 21.060274 | E905: 2026 | F905: 1 | G905: 0 | H905: 0 | I905: 0 | J905: 0 | K905: 0 | L905: -3.78 | M905: -3.36 | N905: -2.61 | O905: =IF(_xlfn.XLOOKUP(Table323[[#This Row],[player]],consensus!A:A,consensus!A:A,0,0)<>0,1,0) -> 0
... A1198: 1099 | B1198: Ty Pence | C1198: Illinois St. | D1198: 22.060274 | E1198: 2026 | F1198: 1 | G1198: 0 | H1198: 0 | I1198: 0 | J1198: 0 | K1198: 0 | L1198: -3.83 | M1198: -3.52 | N1198: -2.96 | O1198: =IF(_xlfn.XLOOKUP(Table323[[#This Row],[player]],consensus!A:A,consensus!A:A,0,0)<>0,1,0) -> 0
A1199: 2491 | B1199: Brycen Blaine | C1199: Charleston Southern | E1199: 2026 | F1199: 1 | G1199: 0 | H1199: 0 | I1199: 0 | J1199: 0 | K1199: 0 | L1199: -3.8 | M1199: -3.52 | N1199: -2.99 | O1199: =IF(_xlfn.XLOOKUP(Table323[[#This Row],[player]],consensus!A:A,consensus!A:A,0,0)<>0,1,0) -> 0
A1200: 1945 | B1200: Vaughn Weems | C1200: Nevada | D1200: 22.060274 | E1200: 2026 | F1200: 1 | G1200: 0 | H1200: 0 | I1200: 0 | J1200: 0 | K1200: 0 | L1200: -3.79 | M1200: -3.52 | N1200: -3.01 | O1200: =IF(_xlfn.XLOOKUP(Table323[[#This Row],[player]],consensus!A:A,consensus!A:A,0,0)<>0,1,0) -> 0
A1201: 1314 | B1201: Sonny Wilson | C1201: Toledo | D1201: 22.060274 | E1201: 2026 | F1201: 1 | G1201: 0 | H1201: 0 | I1201: 0 | J1201: 0 | K1201: 0 | L1201: -3.81 | M1201: -3.52 | N1201: -3.02 | O1201: =IF(_xlfn.XLOOKUP(Table323[[#This Row],[player]],consensus!A:A,consensus!A:A,0,0)<>0,1,0) -> 0
A1202: 1560 | B1202: Dominick Stewart | C1202: Penn St. | D1202: 21.060274 | E1202: 2026 | F1202: 1 | G1202: 0 | H1202: 0 | I1202: 0 | J1202: 0 | K1202: 0 | L1202: -3.78 | M1202: -3.52 | N1202: -3.05 | O1202: =IF(_xlfn.XLOOKUP(Table323[[#This Row],[player]],consensus!A:A,consensus!A:A,0,0)<>0,1,0) -> 0
A1203: 1619 | B1203: Tyler Betsey | C1203: Syracuse | D1203: 21.263014 | E1203: 2026 | F1203: 1 | G1203: 0 | H1203: 0 | I1203: 0 | J1203: 0 | K1203: 0 | L1203: -3.57 | M1203: -3.52 | N1203: -3.18 | O1203: =IF(_xlfn.XLOOKUP(Table323[[#This Row],[player]],consensus!A:A,consensus!A:A,0,0)<>0,1,0) -> 0
A1204: 2133 | B1204: Rob Diaz | C1204: Long Beach St. | D1204: 22.060274 | E1204: 2026 | F1204: 1 | G1204: 0 | H1204: 0 | I1204: 0 | J1204: 0 | K1204: 0 | L1204: -3.55 | M1204: -3.52 | N1204: -3.29 | O1204: =IF(_xlfn.XLOOKUP(Table323[[#This Row],[player]],consensus!A:A,consensus!A:A,0,0)<>0,1,0) -> 0
A1205: 308 | B1205: Kenyon Giles | C1205: Wichita St. | D1205: 23.063014 | E1205: 2026 | F1205: 1 | G1205: 0 | H1205: 0 | I1205: 0 | J1205: 0 | K1205: 0 | L1205: -3.85 | M1205: -3.53 | N1205: -2.76 | O1205: =IF(_xlfn.XLOOKUP(Table323[[#This Row],[player]],consensus!A:A,consensus!A:A,0,0)<>0,1,0) -> 0
A1206: 610 | B1206: Tyeree Bryan | C1206: Texas Tech | D1206: 24.063014 | E1206: 2026 | F1206: 1 | G1206: 0 | H1206: 0 | I1206: 0 | J1206: 0 | K1206: 0 | L1206: -3.84 | M1206: -3.53 | N1206: -2.76 | O1206: =IF(_xlfn.XLOOKUP(Table323[[#This Row],[player]],consensus!A:A,consensus!A:A,0,0)<>0,1,0) -> 0
A1207: 1200 | B1207: Kolton Mitchell | C1207: Idaho | D1207: 22.060274 | E1207: 2026 | F1207: 1 | G1207: 0 | H1207: 0 | I1207: 0 | J1207: 0 | K1207: 0 | L1207: -3.86 | M1207: -3.53 | N1207: -2.82 | O1207: =IF(_xlfn.XLOOKUP(Table323[[#This Row],[player]],consensus!A:A,consensus!A:A,0,0)<>0,1,0) -> 0
A1208: 2425 | B1208: Luka Vudragovic | C1208: Pepperdine | D1208: 20.060274 | E1208: 2026 | F1208: 1 | G1208: 0 | H1208: 0 | I1208: 0 | J1208: 0 | K1208: 0 | L1208: -3.85 | M1208: -3.53 | N1208: -2.86 | O1208: =IF(_xlfn.XLOOKUP(Table323[[#This Row],[player]],consensus!A:A,consensus!A:A,0,0)<>0,1,0) -> 0
A1209: 1938 | B1209: Noah Norgaard | C1209: UNC Greensboro | D1209: 19.128767 | E1209: 2026 | F1209: 1 | G1209: 0 | H1209: 0 | I1209: 0 | J1209: 0 | K1209: 0 | L1209: -3.86 | M1209: -3.53 | N1209: -2.92 | O1209: =IF(_xlfn.XLOOKUP(Table323[[#This Row],[player]],consensus!A:A,consensus!A:A,0,0)<>0,1,0) -> 0
A1210: 1183 | B1210: Gavin Walsh | C1210: UNC Wilmington | D1210: 22.060274 | E1210: 2026 | F1210: 1 | G1210: 0 | H1210: 0 | I1210: 0 | J1210: 0 | K1210: 0 | L1210: -3.84 | M1210: -3.53 | N1210: -2.94 | O1210: =IF(_xlfn.XLOOKUP(Table323[[#This Row],[player]],consensus!A:A,consensus!A:A,0,0)<>0,1,0) -> 0
...

Sheet 2025
A1: Column1 | B1: player | C1: team | D1: age | E1: season | F1: bust | G1: rotation | H1: starter | I1: all star | J1: all nba | K1: mvp | L1: 5th | M1: median | N1: 95th | O1: consensus
A2: 2463 | B2: Cooper Flagg | C2: Duke | D2: 18.876712 | E2: 2025 | F2: 0 | G2: 0.029 | H2: 0.277 | I2: 0.307 | J2: 0.352 | K2: 0.035 | L2: 0.11 | M2: 1.61 | N2: 4.2 | O2: =IF(_xlfn.XLOOKUP(Table3235[[#This Row],[player]],consensus!B:B,consensus!B:B,0,0)<>0,1,0) -> 1
A3: 2182 | B3: Derik Queen | C3: Maryland | D3: 20.860274 | E3: 2025 | F3: 0.01 | G3: 0.179 | H3: 0.336 | I3: 0.268 | J3: 0.199 | K3: 0.008 | L3: -0.58 | M3: 0.93 | N3: 3.25 | O3: =IF(_xlfn.XLOOKUP(Table3235[[#This Row],[player]],consensus!B:B,consensus!B:B,0,0)<>0,1,0) -> 1
A4: 2366 | B4: Kasparas Jakucionis | C4: Illinois | D4: 19.441096 | E4: 2025 | F4: 0.016 | G4: 0.215 | H4: 0.325 | I4: 0.238 | J4: 0.196 | K4: 0.011 | L4: -0.7 | M4: 0.82 | N4: 3.36 | O4: =IF(_xlfn.XLOOKUP(Table3235[[#This Row],[player]],consensus!B:B,consensus!B:B,0,0)<>0,1,0) -> 1
A5: 2329 | B5: V.J. Edgecombe | C5: Baylor | D5: 20.271233 | E5: 2025 | F5: 0.061 | G5: 0.218 | H5: 0.313 | I5: 0.232 | J5: 0.17 | K5: 0.006 | L5: -1.09 | M5: 0.7 | N5: 3.12 | O5: =IF(_xlfn.XLOOKUP(Table3235[[#This Row],[player]],consensus!B:B,consensus!B:B,0,0)<>0,1,0) -> 1
A6: 25 | B6: Ben Saraf | C6: Ratiopharm Ulm | D6: 19.564384 | E6: 2025 | F6: 0.04 | G6: 0.259 | H6: 0.311 | I6: 0.214 | J6: 0.167 | K6: 0.009 | L6: -0.93 | M6: 0.62 | N6: 3.2 | O6: =IF(_xlfn.XLOOKUP(Table3235[[#This Row],[player]],consensus!B:B,consensus!B:B,0,0)<>0,1,0) -> 1
A7: 2470 | B7: Thomas Sorber | C7: Georgetown | D7: 19.865753 | E7: 2025 | F7: 0.161 | G7: 0.216 | H7: 0.235 | I7: 0.181 | J7: 0.185 | K7: 0.02 | L7: -1.79 | M7: 0.5 | N7: 3.66 | O7: =IF(_xlfn.XLOOKUP(Table3235[[#This Row],[player]],consensus!B:B,consensus!B:B,0,0)<>0,1,0) -> 1
A8: 2496 | B8: Dylan Harper | C8: Rutgers | D8: 19.682192 | E8: 2025 | F8: 0.073 | G8: 0.286 | H8: 0.294 | I8: 0.197 | J8: 0.143 | K8: 0.008 | L8: -1.13 | M8: 0.45 | N8: 3.05 | O8: =IF(_xlfn.XLOOKUP(Table3235[[#This Row],[player]],consensus!B:B,consensus!B:B,0,0)<>0,1,0) -> 1
A9: 2395 | B9: Jeremiah Fears | C9: Oklahoma | D9: 19.063014 | E9: 2025 | F9: 0.06 | G9: 0.331 | H9: 0.298 | I9: 0.186 | J9: 0.12 | K9: 0.005 | L9: -1.04 | M9: 0.33 | N9: 2.84 | O9: =IF(_xlfn.XLOOKUP(Table3235[[#This Row],[player]],consensus!B:B,consensus!B:B,0,0)<>0,1,0) -> 1
A10: 2361 | B10: Asa Newell | C10: Georgia | D10: 20.087671 | E10: 2025 | F10: 0.158 | G10: 0.262 | H10: 0.29 | I10: 0.184 | J10: 0.104 | K10: 0.002 | L10: -1.74 | M10: 0.26 | N10: 2.57 | O10: =IF(_xlfn.XLOOKUP(Table3235[[#This Row],[player]],consensus!B:B,consensus!B:B,0,0)<>0,1,0) -> 1
A11: 17 | B11: Noa Essengue | C11: Ratiopharm Ulm | D11: 18.884932 | E11: 2025 | F11: 0.175 | G11: 0.261 | H11: 0.265 | I11: 0.173 | J11: 0.121 | K11: 0.006 | L11: -1.81 | M11: 0.22 | N11: 2.87 | O11: =IF(_xlfn.XLOOKUP(Table3235[[#This Row],[player]],consensus!B:B,consensus!B:B,0,0)<>0,1,0) -> 1
A12: 2315 | B12: Egor Demin | C12: BYU | D12: 19.679452 | E12: 2025 | F12: 0.094 | G12: 0.333 | H12: 0.289 | I12: 0.17 | J12: 0.108 | K12: 0.006 | L12: -1.18 | M12: 0.22 | N12: 2.77 | O12: =IF(_xlfn.XLOOKUP(Table3235[[#This Row],[player]],consensus!B:B,consensus!B:B,0,0)<>0,1,0) -> 1
A13: 18 | B13: Nolan Traore | C13: Saint Quentin Basketball | D13: 19.443836 | E13: 2025 | F13: 0.114 | G13: 0.32 | H13: 0.285 | I13: 0.168 | J13: 0.11 | K13: 0.004 | L13: -1.3 | M13: 0.2 | N13: 2.72 | O13: =IF(_xlfn.XLOOKUP(Table3235[[#This Row],[player]],consensus!B:B,consensus!B:B,0,0)<>0,1,0) -> 1
... A2061: 2300 | B2061: Ben Tweedy | C2061: Green Bay | D2061: 20.060274 | E2061: 2025 | F2061: 1 | G2061: 0 | H2061: 0 | I2061: 0 | J2061: 0 | K2061: 0 | L2061: -4 | M2061: -3.98 | N2061: -3.95 | O2061: =IF(_xlfn.XLOOKUP(Table3235[[#This Row],[player]],consensus!B:B,consensus!B:B,0,0)<>0,1,0) -> 0

Sheet 2024
A1: Column1 | B1: player | C1: team | D1: age | E1: season | F1: bust | G1: rotation | H1: starter | I1: all star | J1: all nba | K1: mvp | L1: 5th | M1: median | N1: 95th | O1: consensus
A2: 28 | B2: Ron Holland | C2: NBA G League Ignite | D2: 19.334247 | E2: 2024 | F2: 0.033 | G2: 0.214 | H2: 0.275 | I2: 0.222 | J2: 0.228 | K2: 0.028 | L2: -0.87 | M2: 0.92 | N2: 3.92 | O2: =IF(_xlfn.XLOOKUP(Table37[[#This Row],[player]],consensus!C:C,consensus!C:C,0,0)<>0,1,0) -> 1
A3: 26 | B3: Alex Sarr | C3: Perth | D3: 19.531507 | E3: 2024 | F3: 0.004 | G3: 0.245 | H3: 0.324 | I3: 0.233 | J3: 0.184 | K3: 0.01 | L3: -0.7 | M3: 0.75 | N3: 3.29 | O3: =IF(_xlfn.XLOOKUP(Table37[[#This Row],[player]],consensus!C:C,consensus!C:C,0,0)<>0,1,0) -> 1
A4: 15 | B4: Nikola Topic | C4: KK Mega Bemax KK Crvena Zvezda | D4: 19.241096 | E4: 2024 | F4: 0.007 | G4: 0.283 | H4: 0.318 | I4: 0.214 | J4: 0.167 | K4: 0.01 | L4: -0.76 | M4: 0.63 | N4: 3.23 | O4: =IF(_xlfn.XLOOKUP(Table37[[#This Row],[player]],consensus!C:C,consensus!C:C,0,0)<>0,1,0) -> 1
A5: 2230 | B5: Stephon Castle | C5: Connecticut | D5: 20.013699 | E5: 2024 | F5: 0.055 | G5: 0.33 | H5: 0.317 | I5: 0.185 | J5: 0.109 | K5: 0.003 | L5: -1.02 | M5: 0.33 | N5: 2.7 | O5: =IF(_xlfn.XLOOKUP(Table37[[#This Row],[player]],consensus!C:C,consensus!C:C,0,0)<>0,1,0) -> 1
A6: 1784 | B6: Kyle Filipowski | C6: Duke | D6: 21 | E6: 2024 | F6: 0.088 | G6: 0.335 | H6: 0.3 | I6: 0.172 | J6: 0.101 | K6: 0.004 | L6: -1.16 | M6: 0.22 | N6: 2.64 | O6: =IF(_xlfn.XLOOKUP(Table37[[#This Row],[player]],consensus!C:C,consensus!C:C,0,0)<>0,1,0) -> 1
A7: 89 | B7: Jean Montero | C7: MoraBanc Andorra | D7: 21.347945 | E7: 2024 | F7: 0.182 | G7: 0.275 | H7: 0.241 | I7: 0.159 | J7: 0.133 | K7: 0.01 | L7: -1.71 | M7: 0.16 | N7: 3.13 | O7: =IF(_xlfn.XLOOKUP(Table37[[#This Row],[player]],consensus!C:C,consensus!C:C,0,0)<>0,1,0) -> 0
A8: 17 | B8: Matas Buzelis | C8: NBA G League Ignite | D8: 20.065753 | E8: 2024 | F8: 0.168 | G8: 0.317 | H8: 0.25 | I8: 0.151 | J8: 0.107 | K8: 0.006 | L8: -1.43 | M8: 0.05 | N8: 2.79 | O8: =IF(_xlfn.XLOOKUP(Table37[[#This Row],[player]],consensus!C:C,consensus!C:C,0,0)<>0,1,0) -> 1
A9: 2301 | B9: Carlton Carrington | C9: Pittsburgh | D9: 19.29589 | E9: 2024 | F9: 0.133 | G9: 0.391 | H9: 0.288 | I9: 0.134 | J9: 0.053 | K9: 0.001 | L9: -1.29 | M9: -0.06 | N9: 2.05 | O9: =IF(_xlfn.XLOOKUP(Table37[[#This Row],[player]],consensus!C:C,consensus!C:C,0,0)<>0,1,0) -> 1
A10: 2343 | B10: Reed Sheppard | C10: Kentucky | D10: 20.369863 | E10: 2024 | F10: 0.213 | G10: 0.313 | H10: 0.241 | I10: 0.141 | J10: 0.089 | K10: 0.004 | L10: -1.62 | M10: -0.09 | N10: 2.61 | O10: =IF(_xlfn.XLOOKUP(Table37[[#This Row],[player]],consensus!C:C,consensus!C:C,0,0)<>0,1,0) -> 1
A11: 18 | B11: Zaccharie Risacher | C11: JL Bourg en Bresse | D11: 19.580822 | E11: 2024 | F11: 0.209 | G11: 0.344 | H11: 0.258 | I11: 0.126 | J11: 0.061 | K11: 0.001 | L11: -1.65 | M11: -0.16 | N11: 2.17 | O11: =IF(_xlfn.XLOOKUP(Table37[[#This Row],[player]],consensus!C:C,consensus!C:C,0,0)<>0,1,0) -> 1
A12: 2559 | B12: Rob Dillingham | C12: Kentucky | D12: 19.838356 | E12: 2024 | F12: 0.213 | G12: 0.339 | H12: 0.243 | I12: 0.128 | J12: 0.075 | K12: 0.002 | L12: -1.55 | M12: -0.17 | N12: 2.39 | O12: =IF(_xlfn.XLOOKUP(Table37[[#This Row],[player]],consensus!C:C,consensus!C:C,0,0)<>0,1,0) -> 1
A13: 2302 | B13: Isaiah Collier | C13: USC | D13: 20.079452 | E13: 2024 | F13: 0.23 | G13: 0.336 | H13: 0.238 | I13: 0.127 | J13: 0.068 | K13: 0.002 | L13: -1.67 | M13: -0.2 | N13: 2.27 | O13: =IF(_xlfn.XLOOKUP(Table37[[#This Row],[player]],consensus!C:C,consensus!C:C,0,0)<>0,1,0) -> 1
... A2045: 1517 | B2045: Aladji Gassama | C2045: Pepperdine | D2045: 22.063014 | E2045: 2024 | F2045: 1 | G2045: 0 | H2045: 0 | I2045: 0 | J2045: 0 | K2045: 0 | L2045: -3.99 | M2045: -3.97 | N2045: -3.93 | O2045: =IF(_xlfn.XLOOKUP(Table37[[#This Row],[player]],consensus!C:C,consensus!C:C,0,0)<>0,1,0) -> 0

Sheet 2023
A1: Column1 | B1: player | C1: team | D1: age | E1: season | F1: bust | G1: rotation | H1: starter | I1: all star | J1: all nba | K1: mvp | L1: 5th | M1: median | N1: 95th | O1: consensus
A2: 2299 | B2: Brandon Miller | C2: Alabama | D2: 20.956164 | E2: 2023 | F2: 0.026 | G2: 0.232 | H2: 0.301 | I2: 0.223 | J2: 0.202 | K2: 0.016 | L2: -0.81 | M2: 0.79 | N2: 3.56 | O2: =IF(_xlfn.XLOOKUP(Table3[[#This Row],[player]],consensus!D:D,consensus!D:D,0,0)<>0,1,0) -> 1
A3: 48 | B3: Victor Wembanyama | C3: Boulogne Levallois | D3: 19.838356 | E3: 2023 | F3: 0.012 | G3: 0.229 | H3: 0.337 | I3: 0.239 | J3: 0.174 | K3: 0.008 | L3: -0.7 | M3: 0.75 | N3: 3.2 | O3: =IF(_xlfn.XLOOKUP(Table3[[#This Row],[player]],consensus!D:D,consensus!D:D,0,0)<>0,1,0) -> 1
A4: 2300 | B4: Anthony Black | C4: Arkansas | D4: 19.794521 | E4: 2023 | F4: 0.084 | G4: 0.218 | H4: 0.281 | I4: 0.215 | J4: 0.189 | K4: 0.013 | L4: -1.27 | M4: 0.69 | N4: 3.43 | O4: =IF(_xlfn.XLOOKUP(Table3[[#This Row],[player]],consensus!D:D,consensus!D:D,0,0)<>0,1,0) -> 1
A5: 2343 | B5: Kyle Filipowski | C5: Duke | D5: 19.99726 | E5: 2023 | F5: 0.026 | G5: 0.306 | H5: 0.304 | I5: 0.2 | J5: 0.154 | K5: 0.009 | L5: -0.9 | M5: 0.52 | N5: 3.17 | O5: =IF(_xlfn.XLOOKUP(Table3[[#This Row],[player]],consensus!D:D,consensus!D:D,0,0)<>0,1,0) -> 0
A6: 2348 | B6: Taylor Hendricks | C6: UCF | D6: 19.956164 | E6: 2023 | F6: 0.168 | G6: 0.235 | H6: 0.252 | I6: 0.19 | J6: 0.148 | K6: 0.008 | L6: -1.89 | M6: 0.37 | N6: 3.09 | O6: =IF(_xlfn.XLOOKUP(Table3[[#This Row],[player]],consensus!D:D,consensus!D:D,0,0)<>0,1,0) -> 1
A7: 2569 | B7: Keyonte George | C7: Baylor | D7: 19.994521 | E7: 2023 | F7: 0.068 | G7: 0.308 | H7: 0.306 | I7: 0.193 | J7: 0.12 | K7: 0.005 | L7: -1.08 | M7: 0.37 | N7: 2.83 | O7: =IF(_xlfn.XLOOKUP(Table3[[#This Row],[player]],consensus!D:D,consensus!D:D,0,0)<>0,1,0) -> 1
A8: 2533 | B8: Gradey Dick | C8: Kansas | D8: 19.961644 | E8: 2023 | F8: 0.033 | G8: 0.344 | H8: 0.321 | I8: 0.185 | J8: 0.114 | K8: 0.003 | L8: -0.93 | M8: 0.34 | N8: 2.72 | O8: =IF(_xlfn.XLOOKUP(Table3[[#This Row],[player]],consensus!D:D,consensus!D:D,0,0)<>0,1,0) -> 1
A9: 2272 | B9: Jarace Walker | C9: Houston | D9: 20.172603 | E9: 2023 | F9: 0.099 | G9: 0.317 | H9: 0.326 | I9: 0.175 | J9: 0.083 | K9: 0.001 | L9: -1.29 | M9: 0.24 | N9: 2.37 | O9: =IF(_xlfn.XLOOKUP(Table3[[#This Row],[player]],consensus!D:D,consensus!D:D,0,0)<>0,1,0) -> 1
A10: 2604 | B10: Guillermo Diaz Graham | C10: Pittsburgh | D10: 20.356164 | E10: 2023 | F10: 0.166 | G10: 0.276 | H10: 0.24 | I10: 0.17 | J10: 0.136 | K10: 0.01 | L10: -1.62 | M10: 0.21 | N10: 3.22 | O10: =IF(_xlfn.XLOOKUP(Table3[[#This Row],[player]],consensus!D:D,consensus!D:D,0,0)<>0,1,0) -> 0
A11: 2367 | B11: Cason Wallace | C11: Kentucky | D11: 19.99726 | E11: 2023 | F11: 0.132 | G11: 0.335 | H11: 0.295 | I11: 0.158 | J11: 0.078 | K11: 0.001 | L11: -1.38 | M11: 0.09 | N11: 2.35 | O11: =IF(_xlfn.XLOOKUP(Table3[[#This Row],[player]],consensus!D:D,consensus!D:D,0,0)<>0,1,0) -> 1
A12: 1782 | B12: Brandin Podziemski | C12: Santa Clara | D12: 20.69589 | E12: 2023 | F12: 0.167 | G12: 0.359 | H12: 0.284 | I12: 0.133 | J12: 0.055 | K12: 0.001 | L12: -1.51 | M12: -0.07 | N12: 2.08 | O12: =IF(_xlfn.XLOOKUP(Table3[[#This Row],[player]],consensus!D:D,consensus!D:D,0,0)<>0,1,0) -> 1
A13: 2514 | B13: Noah Clowney | C13: Alabama | D13: 19.312329 | E13: 2023 | F13: 0.294 | G13: 0.311 | H13: 0.233 | I13: 0.112 | J13: 0.05 | K13: 0.001 | L13: -2.04 | M13: -0.35 | N13: 2.01 | O13: =IF(_xlfn.XLOOKUP(Table3[[#This Row],[player]],consensus!D:D,consensus!D:D,0,0)<>0,1,0) -> 1
... A2089: 1913 | B2089: Touko Tainamo | C2089: Denver | D2089: 22.832877 | E2089: 2023 | F2089: 1 | G2089: 0 | H2089: 0 | I2089: 0 | J2089: 0 | K2089: 0 | L2089: -3.99 | M2089: -3.97 | N2089: -3.92 | O2089: =IF(_xlfn.XLOOKUP(Table3[[#This Row],[player]],consensus!D:D,consensus!D:D,0,0)<>0,1,0) -> 0

Sheet 2022
A1: Column1 | B1: player | C1: team | D1: age | E1: season | F1: bust | G1: rotation | H1: starter | I1: all star | J1: all nba | K1: mvp | L1: 5th | M1: median | N1: 95th | O1: consensus
A2: 2638 | B2: Chet Holmgren | C2: Gonzaga | D2: 20.517808 | E2: 2022 | F2: 0.036 | G2: 0.137 | H2: 0.251 | I2: 0.252 | J2: 0.293 | K2: 0.031 | L2: -0.82 | M2: 1.29 | N2: 4.08 | O2: =IF(_xlfn.XLOOKUP(Table3236[[#This Row],[player]],consensus!E:E,consensus!E:E,0,0)<>0,1,0) -> 1
A3: 2524 | B3: Paolo Banchero | C3: Duke | D3: 19.983562 | E3: 2022 | F3: 0.026 | G3: 0.232 | H3: 0.351 | I3: 0.24 | J3: 0.145 | K3: 0.005 | L3: -0.79 | M3: 0.67 | N3: 2.9 | O3: =IF(_xlfn.XLOOKUP(Table3236[[#This Row],[player]],consensus!E:E,consensus!E:E,0,0)<>0,1,0) -> 1
A4: 2465 | B4: Jabari Smith | C4: Auburn | D4: 19.484932 | E4: 2022 | F4: 0.063 | G4: 0.275 | H4: 0.315 | I4: 0.208 | J4: 0.134 | K4: 0.005 | L4: -1.09 | M4: 0.49 | N4: 2.92 | O4: =IF(_xlfn.XLOOKUP(Table3236[[#This Row],[player]],consensus!E:E,consensus!E:E,0,0)<>0,1,0) -> 1
A5: 1814 | B5: Tari Eason | C5: LSU | D5: 21.493151 | E5: 2022 | F5: 0.179 | G5: 0.234 | H5: 0.224 | I5: 0.169 | J5: 0.172 | K5: 0.023 | L5: -1.82 | M5: 0.37 | N5: 3.69 | O5: =IF(_xlfn.XLOOKUP(Table3236[[#This Row],[player]],consensus!E:E,consensus!E:E,0,0)<>0,1,0) -> 1
A6: 2146 | B6: Keegan Murray | C6: Iowa | D6: 22.216438 | E6: 2022 | F6: 0.203 | G6: 0.258 | H6: 0.258 | I6: 0.16 | J6: 0.115 | K6: 0.006 | L6: -2.03 | M6: 0.14 | N6: 2.84 | O6: =IF(_xlfn.XLOOKUP(Table3236[[#This Row],[player]],consensus!E:E,consensus!E:E,0,0)<>0,1,0) -> 1
A7: 2614 | B7: Kennedy Chandler | C7: Tennessee | D7: 20.139726 | E7: 2022 | F7: 0.224 | G7: 0.257 | H7: 0.244 | I7: 0.158 | J7: 0.111 | K7: 0.005 | L7: -2.13 | M7: 0.07 | N7: 2.8 | O7: =IF(_xlfn.XLOOKUP(Table3236[[#This Row],[player]],consensus!E:E,consensus!E:E,0,0)<>0,1,0) -> 1
A8: 2473 | B8: Josh Minott | C8: Memphis | D8: 19.947945 | E8: 2022 | F8: 0.179 | G8: 0.322 | H8: 0.268 | I8: 0.148 | J8: 0.081 | K8: 0.002 | L8: -1.57 | M8: 0 | N8: 2.46 | O8: =IF(_xlfn.XLOOKUP(Table3236[[#This Row],[player]],consensus!E:E,consensus!E:E,0,0)<>0,1,0) -> 1
A9: 2057 | B9: Zach Edey | C9: Purdue | D9: 20.482192 | E9: 2022 | F9: 0.218 | G9: 0.303 | H9: 0.249 | I9: 0.139 | J9: 0.087 | K9: 0.003 | L9: -1.78 | M9: -0.07 | N9: 2.56 | O9: =IF(_xlfn.XLOOKUP(Table3236[[#This Row],[player]],consensus!E:E,consensus!E:E,0,0)<>0,1,0) -> 0
A10: 6 | B10: Dyson Daniels | C10: NBA G League Ignite | D10: 19.641096 | E10: 2022 | F10: 0.267 | G10: 0.266 | H10: 0.231 | I10: 0.136 | J10: 0.096 | K10: 0.005 | L10: -2.25 | M10: -0.13 | N10: 2.69 | O10: =IF(_xlfn.XLOOKUP(Table3236[[#This Row],[player]],consensus!E:E,consensus!E:E,0,0)<>0,1,0) -> 1
A11: 10 | B11: Nikola Jovic | C11: KK Mega Bemax | D11: 19.410959 | E11: 2022 | F11: 0.283 | G11: 0.298 | H11: 0.23 | I11: 0.123 | J11: 0.064 | K11: 0.002 | L11: -2.24 | M11: -0.27 | N11: 2.23 | O11: =IF(_xlfn.XLOOKUP(Table3236[[#This Row],[player]],consensus!E:E,consensus!E:E,0,0)<>0,1,0) -> 1
A12: 673 | B12: Trevion Williams | C12: Purdue | D12: 22.139726 | E12: 2022 | F12: 0.261 | G12: 0.35 | H12: 0.229 | I12: 0.107 | J12: 0.051 | K12: 0.001 | L12: -1.63 | M12: -0.35 | N12: 2.03 | O12: =IF(_xlfn.XLOOKUP(Table3236[[#This Row],[player]],consensus!E:E,consensus!E:E,0,0)<>0,1,0) -> 1
A13: 1910 | B13: Walker Kessler | C13: Auburn | D13: 21.282192 | E13: 2022 | F13: 0.335 | G13: 0.259 | H13: 0.211 | I13: 0.12 | J13: 0.073 | K13: 0.003 | L13: -2.51 | M13: -0.37 | N13: 2.37 | O13: =IF(_xlfn.XLOOKUP(Table3236[[#This Row],[player]],consensus!E:E,consensus!E:E,0,0)<>0,1,0) -> 1
... A2017: 2098 | B2017: Nehemiah Benson | C2017: Rider | D2017: 21.060274 | E2017: 2022 | F2017: 1 | G2017: 0 | H2017: 0 | I2017: 0 | J2017: 0 | K2017: 0 | L2017: -3.99 | M2017: -3.98 | N2017: -3.94 | O2017: =IF(_xlfn.XLOOKUP(Table3236[[#This Row],[player]],consensus!E:E,consensus!E:E,0,0)<>0,1,0) -> 0

Sheet 2021
A1: Column1 | B1: player | C1: team | D1: age | E1: season | F1: bust | G1: rotation | H1: starter | I1: all star | J1: all nba | K1: mvp | L1: 5th | M1: median | N1: 95th | O1: consensus
A2: 7 | B2: Alperen Sengun | C2: Besiktas Icrypex | D2: 19.284932 | E2: 2021 | F2: 0 | G2: 0.033 | H2: 0.269 | I2: 0.306 | J2: 0.355 | K2: 0.036 | L2: 0.1 | M2: 1.62 | N2: 4.22 | O2: =IF(_xlfn.XLOOKUP(Table32368[[#This Row],[player]],consensus!F:F,consensus!F:F,0,0)<>0,1,0) -> 1
A3: 2028 | B3: Cade Cunningham | C3: Oklahoma St. | D3: 20.060274 | E3: 2021 | F3: 0.032 | G3: 0.221 | H3: 0.298 | I3: 0.226 | J3: 0.206 | K3: 0.016 | L3: -0.86 | M3: 0.81 | N3: 3.51 | O3: =IF(_xlfn.XLOOKUP(Table32368[[#This Row],[player]],consensus!F:F,consensus!F:F,0,0)<>0,1,0) -> 1
A4: 2087 | B4: Scottie Barnes | C4: Florida St. | D4: 20.265753 | E4: 2021 | F4: 0.006 | G4: 0.246 | H4: 0.35 | I4: 0.232 | J4: 0.16 | K4: 0.006 | L4: -0.69 | M4: 0.69 | N4: 3.07 | O4: =IF(_xlfn.XLOOKUP(Table32368[[#This Row],[player]],consensus!F:F,consensus!F:F,0,0)<>0,1,0) -> 1
A5: 2154 | B5: Evan Mobley | C5: USC | D5: 20.386301 | E5: 2021 | F5: 0.115 | G5: 0.235 | H5: 0.28 | I5: 0.204 | J5: 0.158 | K5: 0.008 | L5: -1.5 | M5: 0.52 | N5: 3.11 | O5: =IF(_xlfn.XLOOKUP(Table32368[[#This Row],[player]],consensus!F:F,consensus!F:F,0,0)<>0,1,0) -> 1
A6: 2314 | B6: Day'Ron Sharpe | C6: North Carolina | D6: 20 | E6: 2021 | F6: 0.15 | G6: 0.247 | H6: 0.262 | I6: 0.186 | J6: 0.145 | K6: 0.01 | L6: -1.67 | M6: 0.37 | N6: 3.2 | O6: =IF(_xlfn.XLOOKUP(Table32368[[#This Row],[player]],consensus!F:F,consensus!F:F,0,0)<>0,1,0) -> 1
A7: 2151 | B7: Jalen Suggs | C7: Gonzaga | D7: 20.427397 | E7: 2021 | F7: 0.114 | G7: 0.284 | H7: 0.28 | I7: 0.177 | J7: 0.138 | K7: 0.008 | L7: -1.39 | M7: 0.34 | N7: 3.06 | O7: =IF(_xlfn.XLOOKUP(Table32368[[#This Row],[player]],consensus!F:F,consensus!F:F,0,0)<>0,1,0) -> 1
A8: 2 | B8: Josh Giddey | C8: Adelaide | D8: 19.073973 | E8: 2021 | F8: 0.164 | G8: 0.278 | H8: 0.263 | I8: 0.165 | J8: 0.125 | K8: 0.006 | L8: -1.67 | M8: 0.2 | N8: 2.91 | O8: =IF(_xlfn.XLOOKUP(Table32368[[#This Row],[player]],consensus!F:F,consensus!F:F,0,0)<>0,1,0) -> 1
A9: 46 | B9: Usman Garuba | C9: Real Madrid | D9: 19.663014 | E9: 2021 | F9: 0.154 | G9: 0.293 | H9: 0.275 | I9: 0.167 | J9: 0.107 | K9: 0.004 | L9: -1.54 | M9: 0.18 | N9: 2.73 | O9: =IF(_xlfn.XLOOKUP(Table32368[[#This Row],[player]],consensus!F:F,consensus!F:F,0,0)<>0,1,0) -> 1
A10: 2385 | B10: Azuolas Tubelis | C10: Arizona | D10: 19.627397 | E10: 2021 | F10: 0.168 | G10: 0.324 | H10: 0.282 | I10: 0.148 | J10: 0.076 | K10: 0.002 | L10: -1.6 | M10: 0.03 | N10: 2.33 | O10: =IF(_xlfn.XLOOKUP(Table32368[[#This Row],[player]],consensus!F:F,consensus!F:F,0,0)<>0,1,0) -> 0
A11: 2298 | B11: Hunter Dickinson | C11: Michigan | D11: 20.947945 | E11: 2021 | F11: 0.19 | G11: 0.331 | H11: 0.266 | I11: 0.138 | J11: 0.073 | K11: 0.002 | L11: -1.63 | M11: -0.07 | N11: 2.32 | O11: =IF(_xlfn.XLOOKUP(Table32368[[#This Row],[player]],consensus!F:F,consensus!F:F,0,0)<>0,1,0) -> 0
A12: 2315 | B12: Isaiah Jackson | C12: Kentucky | D12: 19.821918 | E12: 2021 | F12: 0.286 | G12: 0.232 | H12: 0.211 | I12: 0.144 | J12: 0.117 | K12: 0.009 | L12: -2.47 | M12: -0.08 | N12: 3 | O12: =IF(_xlfn.XLOOKUP(Table32368[[#This Row],[player]],consensus!F:F,consensus!F:F,0,0)<>0,1,0) -> 1
A13: 2172 | B13: Moses Moody | C13: Arkansas | D13: 19.435616 | E13: 2021 | F13: 0.229 | G13: 0.318 | H13: 0.256 | I13: 0.134 | J13: 0.062 | K13: 0.001 | L13: -1.91 | M13: -0.15 | N13: 2.18 | O13: =IF(_xlfn.XLOOKUP(Table32368[[#This Row],[player]],consensus!F:F,consensus!F:F,0,0)<>0,1,0) -> 1
... A2029: 2431 | B2029: Devin Gordon | C2029: Mississippi Valley St. | D2029: 20.060274 | E2029: 2021 | F2029: 1 | G2029: 0 | H2029: 0 | I2029: 0 | J2029: 0 | K2029: 0 | L2029: -4 | M2029: -3.98 | N2029: -3.95 | O2029: =IF(_xlfn.XLOOKUP(Table32368[[#This Row],[player]],consensus!F:F,consensus!F:F,0,0)<>0,1,0) -> 0

Sheet 2020
A1: Column1 | B1: player | C1: team | D1: age | E1: season | F1: bust | G1: rotation | H1: starter | I1: all star | J1: all nba | K1: mvp | L1: 5th | M1: median | N1: 95th | O1: consensus
A2: 28 | B2: LaMelo Ball | C2: Illawarra | D2: 19.208219 | E2: 2020 | F2: 0.049 | G2: 0.295 | H2: 0.305 | I2: 0.198 | J2: 0.146 | K2: 0.007 | L2: -0.99 | M2: 0.47 | N2: 3.04 | O2: =IF(_xlfn.XLOOKUP(Table329[[#This Row],[player]],consensus!G:G,consensus!G:G,0,0)<>0,1,0) -> 1
A3: 12 | B3: Deni Avdija | C3: Maccabi FOX Tel Aviv | D3: 19.841096 | E3: 2020 | F3: 0.071 | G3: 0.289 | H3: 0.305 | I3: 0.192 | J3: 0.137 | K3: 0.006 | L3: -1.12 | M3: 0.43 | N3: 2.97 | O3: =IF(_xlfn.XLOOKUP(Table329[[#This Row],[player]],consensus!G:G,consensus!G:G,0,0)<>0,1,0) -> 1
A4: 16 | B4: Killian Hayes | C4: Ratiopharm Ulm | D4: 19.279452 | E4: 2020 | F4: 0.072 | G4: 0.309 | H4: 0.286 | I4: 0.182 | J4: 0.141 | K4: 0.01 | L4: -1.09 | M4: 0.38 | N4: 3.15 | O4: =IF(_xlfn.XLOOKUP(Table329[[#This Row],[player]],consensus!G:G,consensus!G:G,0,0)<>0,1,0) -> 1
A5: 38 | B5: Marko Simonovic | C5: KK Mega Bemax | D5: 21.063014 | E5: 2020 | F5: 0.077 | G5: 0.293 | H5: 0.285 | I5: 0.19 | J5: 0.145 | K5: 0.01 | L5: -1.12 | M5: 0.36 | N5: 3.14 | O5: =IF(_xlfn.XLOOKUP(Table329[[#This Row],[player]],consensus!G:G,consensus!G:G,0,0)<>0,1,0) -> 1
A6: 2266 | B6: Onyeka Okongwu | C6: USC | D6: 19.90411 | E6: 2020 | F6: 0.182 | G6: 0.243 | H6: 0.252 | I6: 0.178 | J6: 0.138 | K6: 0.007 | L6: -1.88 | M6: 0.28 | N6: 3.02 | O6: =IF(_xlfn.XLOOKUP(Table329[[#This Row],[player]],consensus!G:G,consensus!G:G,0,0)<>0,1,0) -> 1
A7: 2374 | B7: Vernon Carey Jr. | C7: Duke | D7: 19.69589 | E7: 2020 | F7: 0.173 | G7: 0.287 | H7: 0.274 | I7: 0.167 | J7: 0.095 | K7: 0.002 | L7: -1.74 | M7: 0.13 | N7: 2.54 | O7: =IF(_xlfn.XLOOKUP(Table329[[#This Row],[player]],consensus!G:G,consensus!G:G,0,0)<>0,1,0) -> 1
A8: 2005 | B8: Zeke Nnaji | C8: Arizona | D8: 19.824658 | E8: 2020 | F8: 0.189 | G8: 0.308 | H8: 0.275 | I8: 0.155 | J8: 0.071 | K8: 0.001 | L8: -1.75 | M8: 0.01 | N8: 2.28 | O8: =IF(_xlfn.XLOOKUP(Table329[[#This Row],[player]],consensus!G:G,consensus!G:G,0,0)<>0,1,0) -> 1
A9: 2504 | B9: Patrick Williams | C9: Florida St. | D9: 19.19726 | E9: 2020 | F9: 0.219 | G9: 0.298 | H9: 0.277 | I9: 0.14 | J9: 0.065 | K9: 0.001 | L9: -2.01 | M9: -0.06 | N9: 2.18 | O9: =IF(_xlfn.XLOOKUP(Table329[[#This Row],[player]],consensus!G:G,consensus!G:G,0,0)<>0,1,0) -> 1
A10: 1303 | B10: Jalen Smith | C10: Maryland | D10: 20.643836 | E10: 2020 | F10: 0.235 | G10: 0.329 | H10: 0.254 | I10: 0.127 | J10: 0.054 | K10: 0.001 | L10: -1.84 | M10: -0.2 | N10: 2.07 | O10: =IF(_xlfn.XLOOKUP(Table329[[#This Row],[player]],consensus!G:G,consensus!G:G,0,0)<>0,1,0) -> 1
A11: 1180 | B11: Xavier Tillman | C11: Michigan St. | D11: 21.819178 | E11: 2020 | F11: 0.317 | G11: 0.262 | H11: 0.217 | I11: 0.125 | J11: 0.075 | K11: 0.003 | L11: -2.75 | M11: -0.3 | N11: 2.42 | O11: =IF(_xlfn.XLOOKUP(Table329[[#This Row],[player]],consensus!G:G,consensus!G:G,0,0)<>0,1,0) -> 1
A12: 2302 | B12: Trendon Watford | C12: LSU | D12: 19.991781 | E12: 2020 | F12: 0.228 | G12: 0.382 | H12: 0.245 | I12: 0.108 | J12: 0.037 | K12: 0 | L12: -1.62 | M12: -0.31 | N12: 1.8 | O12: =IF(_xlfn.XLOOKUP(Table329[[#This Row],[player]],consensus!G:G,consensus!G:G,0,0)<>0,1,0) -> 0
A13: 2316 | B13: Josh Green | C13: Arizona | D13: 19.972603 | E13: 2020 | F13: 0.299 | G13: 0.305 | H13: 0.228 | I13: 0.115 | J13: 0.053 | K13: 0.001 | L13: -2.23 | M13: -0.35 | N13: 2.06 | O13: =IF(_xlfn.XLOOKUP(Table329[[#This Row],[player]],consensus!G:G,consensus!G:G,0,0)<>0,1,0) -> 1
... A2124: 2188 | B2124: Miles Daniels | C2124: Jackson St. | D2124: 21.339726 | E2124: 2020 | F2124: 1 | G2124: 0 | H2124: 0 | I2124: 0 | J2124: 0 | K2124: 0 | L2124: -3.99 | M2124: -3.98 | N2124: -3.94 | O2124: =IF(_xlfn.XLOOKUP(Table329[[#This Row],[player]],consensus!G:G,consensus!G:G,0,0)<>0,1,0) -> 0

Sheet 2019
A1: Column1 | B1: player | C1: team | D1: age | E1: season | F1: bust | G1: rotation | H1: starter | I1: all star | J1: all nba | K1: mvp | L1: 5th | M1: median | N1: 95th | O1: consensus
A2: 2008 | B2: Zion Williamson | C2: Duke | D2: 19.334247 | E2: 2019 | F2: 0.053 | G2: 0.148 | H2: 0.229 | I2: 0.217 | J2: 0.297 | K2: 0.056 | L2: -1.03 | M2: 1.31 | N2: 4.62 | O2: =IF(_xlfn.XLOOKUP(Table3210[[#This Row],[player]],consensus!H:H,consensus!H:H,0,0)<>0,1,0) -> 1
A3: 1639 | B3: Jarrett Culver | C3: Texas Tech | D3: 20.709589 | E3: 2019 | F3: 0.025 | G3: 0.227 | H3: 0.287 | I3: 0.223 | J3: 0.217 | K3: 0.022 | L3: -0.8 | M3: 0.86 | N3: 3.76 | O3: =IF(_xlfn.XLOOKUP(Table3210[[#This Row],[player]],consensus!H:H,consensus!H:H,0,0)<>0,1,0) -> 1
A4: 2012 | B4: R.J. Barrett | C4: Duke | D4: 19.394521 | E4: 2019 | F4: 0.039 | G4: 0.276 | H4: 0.369 | I4: 0.214 | J4: 0.101 | K4: 0.001 | L4: -0.93 | M4: 0.47 | N4: 2.5 | O4: =IF(_xlfn.XLOOKUP(Table3210[[#This Row],[player]],consensus!H:H,consensus!H:H,0,0)<>0,1,0) -> 1
A5: 1718 | B5: Chuma Okeke | C5: Auburn | D5: 21.219178 | E5: 2019 | F5: 0.19 | G5: 0.213 | H5: 0.25 | I5: 0.184 | J5: 0.152 | K5: 0.011 | L5: -2.4 | M5: 0.37 | N5: 3.2 | O5: =IF(_xlfn.XLOOKUP(Table3210[[#This Row],[player]],consensus!H:H,consensus!H:H,0,0)<>0,1,0) -> 1
A6: 1877 | B6: Jalen Smith | C6: Maryland | D6: 19.641096 | E6: 2019 | F6: 0.134 | G6: 0.306 | H6: 0.296 | I6: 0.177 | J6: 0.086 | K6: 0.001 | L6: -1.5 | M6: 0.18 | N6: 2.44 | O6: =IF(_xlfn.XLOOKUP(Table3210[[#This Row],[player]],consensus!H:H,consensus!H:H,0,0)<>0,1,0) -> 0
A7: 1741 | B7: Xavier Tillman | C7: Michigan St. | D7: 20.816438 | E7: 2019 | F7: 0.163 | G7: 0.314 | H7: 0.265 | I7: 0.158 | J7: 0.096 | K7: 0.004 | L7: -1.53 | M7: 0.08 | N7: 2.61 | O7: =IF(_xlfn.XLOOKUP(Table3210[[#This Row],[player]],consensus!H:H,consensus!H:H,0,0)<>0,1,0) -> 0
A8: 2247 | B8: Tyler Herro | C8: Kentucky | D8: 19.794521 | E8: 2019 | F8: 0.156 | G8: 0.352 | H8: 0.282 | I8: 0.141 | J8: 0.067 | K8: 0.001 | L8: -1.45 | M8: -0.02 | N8: 2.23 | O8: =IF(_xlfn.XLOOKUP(Table3210[[#This Row],[player]],consensus!H:H,consensus!H:H,0,0)<>0,1,0) -> 1
A9: 2355 | B9: Neemias Queta | C9: Utah St. | D9: 20.060274 | E9: 2019 | F9: 0.255 | G9: 0.278 | H9: 0.247 | I9: 0.141 | J9: 0.077 | K9: 0.002 | L9: -2.16 | M9: -0.12 | N9: 2.37 | O9: =IF(_xlfn.XLOOKUP(Table3210[[#This Row],[player]],consensus!H:H,consensus!H:H,0,0)<>0,1,0) -> 0
A10: 798 | B10: Anthony Lamb | C10: Vermont | D10: 21.794521 | E10: 2019 | F10: 0.327 | G10: 0.204 | H10: 0.196 | I10: 0.139 | J10: 0.124 | K10: 0.011 | L10: -3.48 | M10: -0.14 | N10: 3.12 | O10: =IF(_xlfn.XLOOKUP(Table3210[[#This Row],[player]],consensus!H:H,consensus!H:H,0,0)<>0,1,0) -> 0
A11: 2102 | B11: Keldon Johnson | C11: Kentucky | D11: 20.071233 | E11: 2019 | F11: 0.157 | G11: 0.415 | H11: 0.283 | I11: 0.111 | J11: 0.034 | K11: 0 | L11: -1.33 | M11: -0.18 | N11: 1.75 | O11: =IF(_xlfn.XLOOKUP(Table3210[[#This Row],[player]],consensus!H:H,consensus!H:H,0,0)<>0,1,0) -> 1
A12: 1393 | B12: Kaleb Wesson | C12: Ohio St. | D12: 20.273973 | E12: 2019 | F12: 0.248 | G12: 0.315 | H12: 0.236 | I12: 0.125 | J12: 0.074 | K12: 0.003 | L12: -1.97 | M12: -0.22 | N12: 2.4 | O12: =IF(_xlfn.XLOOKUP(Table3210[[#This Row],[player]],consensus!H:H,consensus!H:H,0,0)<>0,1,0) -> 0
A13: 2132 | B13: Naz Reid | C13: LSU | D13: 20.19726 | E13: 2019 | F13: 0.236 | G13: 0.346 | H13: 0.259 | I13: 0.115 | J13: 0.044 | K13: 0 | L13: -1.88 | M13: -0.23 | N13: 1.91 | O13: =IF(_xlfn.XLOOKUP(Table3210[[#This Row],[player]],consensus!H:H,consensus!H:H,0,0)<>0,1,0) -> 1
... A2090: 348 | B2090: Ricky Madison | C2090: High Point | D2090: 22.471233 | E2090: 2019 | F2090: 1 | G2090: 0 | H2090: 0 | I2090: 0 | J2090: 0 | K2090: 0 | L2090: -4 | M2090: -3.98 | N2090: -3.95 | O2090: =IF(_xlfn.XLOOKUP(Table3210[[#This Row],[player]],consensus!H:H,consensus!H:H,0,0)<>0,1,0) -> 0

Sheet 2018
A1: Column1 | B1: player | C1: team | D1: age | E1: season | F1: bust | G1: rotation | H1: starter | I1: all star | J1: all nba | K1: mvp | L1: 5th | M1: median | N1: 95th | O1: consensus
A2: 2314 | B2: Jaren Jackson Jr. | C2: Michigan St. | D2: 19.142466 | E2: 2018 | F2: 0.032 | G2: 0.128 | H2: 0.245 | I2: 0.252 | J2: 0.305 | K2: 0.038 | L2: -0.77 | M2: 1.37 | N2: 4.21 | O2: =IF(_xlfn.XLOOKUP(Table3211[[#This Row],[player]],consensus!I:I,consensus!I:I,0,0)<>0,1,0) -> 1
A3: 48 | B3: Luka Doncic | C3: Real Madrid | D3: 19.687671 | E3: 2018 | F3: 0.001 | G3: 0.14 | H3: 0.295 | I3: 0.256 | J3: 0.275 | K3: 0.034 | L3: -0.4 | M3: 1.23 | N3: 4.11 | O3: =IF(_xlfn.XLOOKUP(Table3211[[#This Row],[player]],consensus!I:I,consensus!I:I,0,0)<>0,1,0) -> 1
A4: 14 | B4: Goga Bitadze | C4: KK Mega Bemax | D4: 19.29863 | E4: 2018 | F4: 0.1 | G4: 0.2 | H4: 0.262 | I4: 0.215 | J4: 0.205 | K4: 0.019 | L4: -1.44 | M4: 0.76 | N4: 3.58 | O4: =IF(_xlfn.XLOOKUP(Table3211[[#This Row],[player]],consensus!I:I,consensus!I:I,0,0)<>0,1,0) -> 0
A5: 1894 | B5: Deandre Ayton | C5: Arizona | D5: 20.290411 | E5: 2018 | F5: 0.031 | G5: 0.225 | H5: 0.33 | I5: 0.243 | J5: 0.164 | K5: 0.006 | L5: -0.84 | M5: 0.72 | N5: 3.04 | O5: =IF(_xlfn.XLOOKUP(Table3211[[#This Row],[player]],consensus!I:I,consensus!I:I,0,0)<>0,1,0) -> 1
A6: 2312 | B6: Wendell Carter Jr. | C6: Duke | D6: 19.558904 | E6: 2018 | F6: 0.067 | G6: 0.233 | H6: 0.309 | I6: 0.227 | J6: 0.157 | K6: 0.007 | L6: -1.12 | M6: 0.62 | N6: 3.06 | O6: =IF(_xlfn.XLOOKUP(Table3211[[#This Row],[player]],consensus!I:I,consensus!I:I,0,0)<>0,1,0) -> 1
A7: 20 | B7: Dzanan Musa | C7: Cedevita | D7: 19.49863 | E7: 2018 | F7: 0.071 | G7: 0.279 | H7: 0.302 | I7: 0.202 | J7: 0.14 | K7: 0.006 | L7: -1.13 | M7: 0.47 | N7: 2.99 | O7: =IF(_xlfn.XLOOKUP(Table3211[[#This Row],[player]],consensus!I:I,consensus!I:I,0,0)<>0,1,0) -> 1
A8: 2196 | B8: Jarrett Culver | C8: Texas Tech | D8: 19.709589 | E8: 2018 | F8: 0.127 | G8: 0.279 | H8: 0.267 | I8: 0.176 | J8: 0.141 | K8: 0.01 | L8: -1.39 | M8: 0.32 | N8: 3.14 | O8: =IF(_xlfn.XLOOKUP(Table3211[[#This Row],[player]],consensus!I:I,consensus!I:I,0,0)<>0,1,0) -> 0
A9: 2254 | B9: Trae Young | C9: Oklahoma | D9: 20.131507 | E9: 2018 | F9: 0.142 | G9: 0.294 | H9: 0.252 | I9: 0.167 | J9: 0.133 | K9: 0.011 | L9: -1.41 | M9: 0.22 | N9: 3.11 | O9: =IF(_xlfn.XLOOKUP(Table3211[[#This Row],[player]],consensus!I:I,consensus!I:I,0,0)<>0,1,0) -> 1
A10: 2047 | B10: Marvin Bagley III | C10: Duke | D10: 19.649315 | E10: 2018 | F10: 0.117 | G10: 0.312 | H10: 0.314 | I10: 0.173 | J10: 0.083 | K10: 0.001 | L10: -1.38 | M10: 0.2 | N10: 2.4 | O10: =IF(_xlfn.XLOOKUP(Table3211[[#This Row],[player]],consensus!I:I,consensus!I:I,0,0)<>0,1,0) -> 1
A11: 2304 | B11: Shai Gilgeous-Alexander | C11: Kentucky | D11: 20.320548 | E11: 2018 | F11: 0.122 | G11: 0.327 | H11: 0.278 | I11: 0.165 | J11: 0.103 | K11: 0.004 | L11: -1.28 | M11: 0.16 | N11: 2.68 | O11: =IF(_xlfn.XLOOKUP(Table3211[[#This Row],[player]],consensus!I:I,consensus!I:I,0,0)<>0,1,0) -> 1
A12: 1289 | B12: Miles Bridges | C12: Michigan St. | D12: 20.630137 | E12: 2018 | F12: 0.25 | G12: 0.297 | H12: 0.249 | I12: 0.132 | J12: 0.07 | K12: 0.003 | L12: -2.23 | M12: -0.15 | N12: 2.33 | O12: =IF(_xlfn.XLOOKUP(Table3211[[#This Row],[player]],consensus!I:I,consensus!I:I,0,0)<>0,1,0) -> 1
A13: 2345 | B13: Jontay Porter | C13: Missouri | D13: 18.975342 | E13: 2018 | F13: 0.234 | G13: 0.314 | H13: 0.25 | I13: 0.132 | J13: 0.069 | K13: 0.002 | L13: -1.87 | M13: -0.15 | N13: 2.3 | O13: =IF(_xlfn.XLOOKUP(Table3211[[#This Row],[player]],consensus!I:I,consensus!I:I,0,0)<>0,1,0) -> 0
... A2058: 2252 | B2058: Alec Hickman | C2058: UC Riverside | D2058: 20.060274 | E2058: 2018 | F2058: 1 | G2058: 0 | H2058: 0 | I2058: 0 | J2058: 0 | K2058: 0 | L2058: -3.99 | M2058: -3.98 | N2058: -3.93 | O2058: =IF(_xlfn.XLOOKUP(Table3211[[#This Row],[player]],consensus!I:I,consensus!I:I,0,0)<>0,1,0) -> 0

Sheet 2017
A1: Column1 | B1: player | C1: team | D1: age | E1: season | F1: bust | G1: rotation | H1: starter | I1: all star | J1: all nba | K1: mvp | L1: 5th | M1: median | N1: 95th | O1: consensus
A2: 1888 | B2: Josh Jackson | C2: Kansas | D2: 20.736986 | E2: 2017 | F2: 0.046 | G2: 0.249 | H2: 0.326 | I2: 0.222 | J2: 0.151 | K2: 0.005 | L2: -0.97 | M2: 0.6 | N2: 3 | O2: =IF(_xlfn.XLOOKUP(Table32[[#This Row],[player]],consensus!J:J,consensus!J:J,0,0)<>0,1,0) -> 1
A3: 2233 | B3: Jonathan Isaac | C3: Florida St. | D3: 20.093151 | E3: 2017 | F3: 0.097 | G3: 0.292 | H3: 0.295 | I3: 0.186 | J3: 0.125 | K3: 0.005 | L3: -1.27 | M3: 0.35 | N3: 2.83 | O3: =IF(_xlfn.XLOOKUP(Table32[[#This Row],[player]],consensus!J:J,consensus!J:J,0,0)<>0,1,0) -> 1
A4: 1935 | B4: Jayson Tatum | C4: Duke | D4: 19.679452 | E4: 2017 | F4: 0.06 | G4: 0.364 | H4: 0.32 | I4: 0.169 | J4: 0.085 | K4: 0.002 | L4: -1.04 | M4: 0.27 | N4: 2.45 | O4: =IF(_xlfn.XLOOKUP(Table32[[#This Row],[player]],consensus!J:J,consensus!J:J,0,0)<>0,1,0) -> 1
A5: 1839 | B5: Miles Bridges | C5: Michigan St. | D5: 19.630137 | E5: 2017 | F5: 0.077 | G5: 0.322 | H5: 0.3 | I5: 0.184 | J5: 0.113 | K5: 0.004 | L5: -1.12 | M5: 0.25 | N5: 2.74 | O5: =IF(_xlfn.XLOOKUP(Table32[[#This Row],[player]],consensus!J:J,consensus!J:J,0,0)<>0,1,0) -> 0
A6: 1605 | B6: Dedric Lawson | C6: Memphis | D6: 20.09863 | E6: 2017 | F6: 0.199 | G6: 0.313 | H6: 0.252 | I6: 0.142 | J6: 0.09 | K6: 0.004 | L6: -1.66 | M6: -0.04 | N6: 2.58 | O6: =IF(_xlfn.XLOOKUP(Table32[[#This Row],[player]],consensus!J:J,consensus!J:J,0,0)<>0,1,0) -> 0
A7: 2153 | B7: De'Anthony Melton | C7: USC | D7: 19.443836 | E7: 2017 | F7: 0.207 | G7: 0.314 | H7: 0.249 | I7: 0.14 | J7: 0.085 | K7: 0.004 | L7: -1.62 | M7: -0.07 | N7: 2.57 | O7: =IF(_xlfn.XLOOKUP(Table32[[#This Row],[player]],consensus!J:J,consensus!J:J,0,0)<>0,1,0) -> 0
A8: 1830 | B8: Lonzo Ball | C8: UCLA | D8: 20.027397 | E8: 2017 | F8: 0.241 | G8: 0.302 | H8: 0.232 | I8: 0.136 | J8: 0.086 | K8: 0.003 | L8: -1.79 | M8: -0.16 | N8: 2.54 | O8: =IF(_xlfn.XLOOKUP(Table32[[#This Row],[player]],consensus!J:J,consensus!J:J,0,0)<>0,1,0) -> 1
A9: 1154 | B9: Caleb Swanigan | C9: Purdue | D9: 20.553425 | E9: 2017 | F9: 0.261 | G9: 0.331 | H9: 0.236 | I9: 0.115 | J9: 0.055 | K9: 0.001 | L9: -2.12 | M9: -0.29 | N9: 2.1 | O9: =IF(_xlfn.XLOOKUP(Table32[[#This Row],[player]],consensus!J:J,consensus!J:J,0,0)<>0,1,0) -> 1
A10: 2073 | B10: Robert Williams | C10: Texas A&M | D10: 20.054795 | E10: 2017 | F10: 0.305 | G10: 0.293 | H10: 0.223 | I10: 0.118 | J10: 0.06 | K10: 0.001 | L10: -2.23 | M10: -0.35 | N10: 2.18 | O10: =IF(_xlfn.XLOOKUP(Table32[[#This Row],[player]],consensus!J:J,consensus!J:J,0,0)<>0,1,0) -> 0
A11: 1987 | B11: Rawle Alkins | C11: Arizona | D11: 20.021918 | E11: 2017 | F11: 0.26 | G11: 0.357 | H11: 0.235 | I11: 0.104 | J11: 0.044 | K11: 0 | L11: -1.75 | M11: -0.35 | N11: 1.9 | O11: =IF(_xlfn.XLOOKUP(Table32[[#This Row],[player]],consensus!J:J,consensus!J:J,0,0)<>0,1,0) -> 0
A12: 1113 | B12: Jawun Evans | C12: Oklahoma St. | D12: 21.060274 | E12: 2017 | F12: 0.32 | G12: 0.28 | H12: 0.197 | I12: 0.115 | J12: 0.082 | K12: 0.005 | L12: -2.03 | M12: -0.38 | N12: 2.58 | O12: =IF(_xlfn.XLOOKUP(Table32[[#This Row],[player]],consensus!J:J,consensus!J:J,0,0)<>0,1,0) -> 1
A13: 1868 | B13: Lauri Markkanen | C13: Arizona | D13: 20.460274 | E13: 2017 | F13: 0.269 | G13: 0.353 | H13: 0.233 | I13: 0.105 | J13: 0.04 | K13: 0.001 | L13: -1.7 | M13: -0.38 | N13: 1.86 | O13: =IF(_xlfn.XLOOKUP(Table32[[#This Row],[player]],consensus!J:J,consensus!J:J,0,0)<>0,1,0) -> 1
... A1961: 980 | B1961: Nate Hickman | C1961: Columbia | D1961: 22.430137 | E1961: 2017 | F1961: 1 | G1961: 0 | H1961: 0 | I1961: 0 | J1961: 0 | K1961: 0 | L1961: -3.97 | M1961: -3.96 | N1961: -3.92 | O1961: =IF(_xlfn.XLOOKUP(Table32[[#This Row],[player]],consensus!J:J,consensus!J:J,0,0)<>0,1,0) -> 0

Sheet 2016
A1: Column1 | B1: player | C1: team | D1: age | E1: season | F1: bust | G1: rotation | H1: starter | I1: all star | J1: all nba | K1: mvp | L1: 5th | M1: median | N1: 95th | O1: consensus
A2: 1972 | B2: Jamal Murray | C2: Kentucky | D2: 19.70137 | E2: 2016 | F2: 0.048 | G2: 0.272 | H2: 0.344 | I2: 0.211 | J2: 0.122 | K2: 0.004 | L2: -0.99 | M2: 0.5 | N2: 2.76 | O2: =IF(_xlfn.XLOOKUP(Table3212[[#This Row],[player]],consensus!K:K,consensus!K:K,0,0)<>0,1,0) -> 1
A3: 1979 | B3: Ben Simmons | C3: LSU | D3: 20.29863 | E3: 2016 | F3: 0.15 | G3: 0.245 | H3: 0.264 | I3: 0.181 | J3: 0.149 | K3: 0.011 | L3: -1.67 | M3: 0.38 | N3: 3.22 | O3: =IF(_xlfn.XLOOKUP(Table3212[[#This Row],[player]],consensus!K:K,consensus!K:K,0,0)<>0,1,0) -> 1
A4: 2110 | B4: Dedric Lawson | C4: Memphis | D4: 19.09863 | E4: 2016 | F4: 0.223 | G4: 0.304 | H4: 0.246 | I4: 0.137 | J4: 0.086 | K4: 0.004 | L4: -1.81 | M4: -0.09 | N4: 2.55 | O4: =IF(_xlfn.XLOOKUP(Table3212[[#This Row],[player]],consensus!K:K,consensus!K:K,0,0)<>0,1,0) -> 0
A5: 1304 | B5: Edmond Sumner | C5: Xavier | D5: 20.852055 | E5: 2016 | F5: 0.256 | G5: 0.296 | H5: 0.227 | I5: 0.131 | J5: 0.084 | K5: 0.005 | L5: -1.82 | M5: -0.19 | N5: 2.55 | O5: =IF(_xlfn.XLOOKUP(Table3212[[#This Row],[player]],consensus!K:K,consensus!K:K,0,0)<>0,1,0) -> 0
A6: 289 | B6: Kris Dunn | C6: Providence | D6: 22.641096 | E6: 2016 | F6: 0.273 | G6: 0.291 | H6: 0.218 | I6: 0.125 | J6: 0.087 | K6: 0.006 | L6: -1.99 | M6: -0.23 | N6: 2.64 | O6: =IF(_xlfn.XLOOKUP(Table3212[[#This Row],[player]],consensus!K:K,consensus!K:K,0,0)<>0,1,0) -> 1
A7: 2148 | B7: Henry Ellenson | C7: Marquette | D7: 19.813699 | E7: 2016 | F7: 0.258 | G7: 0.308 | H7: 0.225 | I7: 0.123 | J7: 0.081 | K7: 0.004 | L7: -1.78 | M7: -0.24 | N7: 2.5 | O7: =IF(_xlfn.XLOOKUP(Table3212[[#This Row],[player]],consensus!K:K,consensus!K:K,0,0)<>0,1,0) -> 1
A8: 71 | B8: Sasha Vezenkov | C8: Barca | D8: 21.254795 | E8: 2016 | F8: 0.307 | G8: 0.315 | H8: 0.214 | I8: 0.107 | J8: 0.055 | K8: 0.001 | L8: -2.15 | M8: -0.41 | N8: 2.1 | O8: =IF(_xlfn.XLOOKUP(Table3212[[#This Row],[player]],consensus!K:K,consensus!K:K,0,0)<>0,1,0) -> 0
A9: 1851 | B9: Brandon Ingram | C9: Duke | D9: 19.178082 | E9: 2016 | F9: 0.313 | G9: 0.324 | H9: 0.212 | I9: 0.101 | J9: 0.049 | K9: 0.001 | L9: -1.92 | M9: -0.45 | N9: 2.01 | O9: =IF(_xlfn.XLOOKUP(Table3212[[#This Row],[player]],consensus!K:K,consensus!K:K,0,0)<>0,1,0) -> 1
A10: 1269 | B10: Isaiah Whitehead | C10: Seton Hall | D10: 21.668493 | E10: 2016 | F10: 0.342 | G10: 0.292 | H10: 0.196 | I10: 0.105 | J10: 0.061 | K10: 0.003 | L10: -1.93 | M10: -0.49 | N10: 2.25 | O10: =IF(_xlfn.XLOOKUP(Table3212[[#This Row],[player]],consensus!K:K,consensus!K:K,0,0)<>0,1,0) -> 1
A11: 1275 | B11: Daniel Hamilton | C11: Connecticut | D11: 21.249315 | E11: 2016 | F11: 0.344 | G11: 0.31 | H11: 0.199 | I11: 0.096 | J11: 0.049 | K11: 0.002 | L11: -1.95 | M11: -0.53 | N11: 2.01 | O11: =IF(_xlfn.XLOOKUP(Table3212[[#This Row],[player]],consensus!K:K,consensus!K:K,0,0)<>0,1,0) -> 1
A12: 1877 | B12: Tyler Lydon | C12: Syracuse | D12: 20.578082 | E12: 2016 | F12: 0.364 | G12: 0.311 | H12: 0.193 | I12: 0.089 | J12: 0.042 | K12: 0.001 | L12: -2.12 | M12: -0.59 | N12: 1.86 | O12: =IF(_xlfn.XLOOKUP(Table3212[[#This Row],[player]],consensus!K:K,consensus!K:K,0,0)<>0,1,0) -> 0
A13: 1227 | B13: Jakob Poeltl | C13: Utah | D13: 21.063014 | E13: 2016 | F13: 0.398 | G13: 0.247 | H13: 0.18 | I13: 0.104 | J13: 0.068 | K13: 0.003 | L13: -2.74 | M13: -0.6 | N13: 2.34 | O13: =IF(_xlfn.XLOOKUP(Table3212[[#This Row],[player]],consensus!K:K,consensus!K:K,0,0)<>0,1,0) -> 1
... A1931: 1708 | B1931: Armani Collins | C1931: Portland St. | D1931: 20.19726 | E1931: 2016 | F1931: 1 | G1931: 0 | H1931: 0 | I1931: 0 | J1931: 0 | K1931: 0 | L1931: -4 | M1931: -3.98 | N1931: -3.96 | O1931: =IF(_xlfn.XLOOKUP(Table3212[[#This Row],[player]],consensus!K:K,consensus!K:K,0,0)<>0,1,0) -> 0

Sheet centroids
A1: cluster | B1: 5th | C1: median | D1: 95th
A2: 1 | B2: -1.3731092 | C2: 0.32008403 | D2: 2.9036134
A3: 2 | B3: -2.3437546 | C3: -0.72925651 | D3: 1.6992193
A4: 3 | B4: -2.766126 | C4: -1.4687977 | D4: 0.65496183
A5: 4 | B5: -3.1207734 | C5: -2.0831886 | D5: -0.16616011
A6: 5 | B6: -3.3342616 | C6: -2.4971754 | D6: -0.89609514
A7: 6 | B7: -3.5513747 | C7: -2.900176 | D7: -1.6025817
A8: 7 | B8: -3.7210473 | C8: -3.2641892 | D8: -2.300777
A9: 8 | B9: -3.8426021 | C9: -3.5827421 | D9: -3.0331389

Sheet consensus
A1: 2026 | B1: 2025 | C1: 2024 | D1: 2023 | E1: 2022 | F1: 2021 | G1: 2020 | H1: 2019 | I1: 2018 | J1: 2017 | K1: 2016
A2: Aday Mara | B2: Ace Bailey | C2: Adem Bona | D2: Adam Flagler | E2: AJ Green | F2: A.J. Lawson | G2: Aaron Nesmith | H2: Adam Mokoka | I2: Aaron Holiday | J2: Alberto Abalde | K2: A.J. English
A3: AJ Dybantsa | B3: Adama-Alpha Bal | C3: AJ Johnson | D3: Adama Sanogo | E3: AJ Griffin | F3: Aamir Simms | G3: Abdoulaye N'Doye | H3: Admiral Schofield | I3: Ajdin Penava | J3: Alec Peters | K3: A.J. Hammons
A4: Alex Condon | B4: Adou Thiero | C4: Ajay Mitchell | D4: Alex Fudge | E4: Alondes Williams | F4: Aaron Henry | G4: Aleksej Pokusevski | H4: Alen Smailagic | I4: Alize Johnson | J4: Sasha Vezenkov | K4: Alex Caruso
A5: Alex Karaban | B5: Alex Toohey | C5: Alex Sarr | D5: Amari Bailey | E5: Aminu Mohammed | F5: Aaron Wiggins | G5: Anthony Cowan | H5: Amir Coffey | I5: Allonzo Trier | J5: Alpha Kaba | K5: Alex Poythress
A6: Alijah Arenas | B6: Alijah Martin | C6: Allen Flanigan | D6: Amen Thompson | E6: Andrew Nembhard | F6: Alperen Sengun | G6: Anthony Edwards | H6: Aubrey Dawkins | I6: Anas Mahmoud | J6: Amida Brimah | K6: Ante Zizic
A7: Amari Allen | B7: Amari Williams | C7: Anton Watson | D7: Andre Jackson Jr. | E7: Bennedict Mathurin | F7: Amar Sylla | G7: Anthony Lamb | H7: Bol Bol | I7: Anfernee Simons | J7: Andrew White III | K7: Anthony Barber
A8: Baba Miller | B8: Andrew Carr | C8: Antonio Reeves | D8: Anthony Black | E8: Blake Wesley | F8: Austin Reaves | G8: Ashton Hagans | H8: Brandon Clarke | I8: Bonzie Colson | J8: Antonio Blakeney | K8: Ben Bentil
A9: Bennett Stirtz | B9: Arthur Kaluma | C9: Ariel Hukporti | D9: Antoine Davis | E9: Brady Manek | F9: Ayo Dosunmu | G9: Austin Wiley | H9: Brian Bowen II | I9: Brandon McCoy | J9: Antonio Campbell | K9: Ben Simmons
A10: Braden Smith | B10: Asa Newell | C10: Armando Bacot | D10: Ausar Thompson | E10: Bryce McGowens | F10: Brandon Boston Jr. | G10: Breein Tyree | H10: Bruno Fernando | I10: Bruce Brown | J10: Anzejs Pasecniks | K10: Brandon Ingram
A11: Brayden Burries | B11: Ben Saraf | C11: Armel Traore | D11: Azuolas Tubelis | E11: Bryson Williams | F11: Cade Cunningham | G11: CJ Elleby | H11: Caleb Martin | I11: Bryant Crawford | J11: Austin Nichols | K11: Brannen Greene
A12: Braylon Mullins | B12: Bogoljub Markovic | C12: Babacar Sane | D12: Ben Sheppard | E12: Buddy Boeheim | F12: Cameron Thomas | G12: Cassius Stanley | H12: Cam Reddish | I12: Chandler Hutchison | J12: Ben Moore | K12: Brice Johnson
A13: Caleb Wilson | B13: Brice Williams | C13: Baylor Scheierman | D13: Bilal Coulibaly | E13: Caleb Houstan | F13: Carlik Jones | G13: Cassius Winston | H13: Cameron Johnson | I13: Chimezie Metu | J13: Caleb Swanigan | K13: Buddy Hield
... A61: Zuby Ejiofor | B61: Kobe Sanders | C61: Malevy Leons | D61: Kobe Bufkin | E61: Kennedy Chandler | F61: Josh Giddey | G61: Myles Powell | H61: Kris Wilkes | I61: Marcus Derrickson | J61: Kris Jenkins | K61: Juancho Hernangomez
B62: Koby Brea | C62: Mantas Rubstavicius | D62: Kris Murray | E62: Kenneth Lofton, Jr. | F62: Joshua Primo | G62: Naji Marshall | H62: Ky Bowman | I62: Marcus Foster | J62: Kyle Kuzma | K62: Kahlil Felder
B63: Kon Knueppel | C63: Marcus Domask | D63: Landers Nolley II | E63: Keon Ellis | F63: JT Thor | G63: Nate Darling | H63: Kyle Guy | I63: Marvin Bagley III | J63: Lauri Markkanen | K63: Kris Dunn
B64: Lachlan Olbrich | C64: Mark Armstrong | D64: Leonard Miller | E64: Khalifa Diop | F64: Juhann Begarin | G64: Nate Hinton | H64: KZ Okpala | I64: Melvin Frazier | J64: London Perrantes | K64: Kyle Collinsworth
B65: Lamont Butler | C65: Matas Buzelis | D65: Liam Robbins | E65: Kofi Cockburn | F65: Justin Champagnie | G65: Nathan Knight | H65: Lamar Peters | I65: Michael Porter Jr. | J65: Lonzo Ball | K65: Kyle Wiltjer
B66: Liam McNeeley | C66: Melvin Ajinca | D66: Malcolm Cazalon | E66: Luke Travers | F66: Kai Jones | G66: Nick Richards | H66: Louis King | I66: Mikal Bridges | J66: Luke Kennard | K66: Malachi Richardson
B67: Mark Sears | C67: Nae'Qwan Tomlin | D67: Marcus Bagley | E67: Makur Maker | F67: Keon Johnson | G67: Nico Mannion | H67: Luguentz Dort | I67: MiKyle McIntosh | J67: Luke Kornet | K67: Malcolm Brogdon
B68: Matt Murrell | C68: N'Faly Dante | D68: Marcus Sasser | E68: Malaki Branham | F68: Kessler Edwards | G68: Obi Toppin | H68: Luka Samanic | I68: Miles Bridges | J68: Malcolm Hill | K68: Malik Beasley
B69: Matthew Cleveland | C69: Nikola Djurisic | D69: Markquis Nowell | E69: Marcus Bingham Jr. | F69: Luka Garza | G69: Omer Yurtseven | H69: Matisse Thybulle | I69: Mitchell Robinson | J69: Malik Monk | K69: Marcus Georges-Hunt
B70: Max Shulga | C70: Nikola Topic | D70: Matthew Mayer | E70: MarJon Beauchamp | F70: M.J. Walker | G70: Onyeka Okongwu | H70: Matt Rafferty | I70: Mohamed Bamba | J70: Marcus Keene | K70: Marcus Paige
B71: Maxime Raynaud | C71: Oso Ighodaro | D71: Maxwell Lewis | E71: Mark Williams | F71: Marcus Garrett | G71: Patrick Williams | H71: Mfiondu Kabengele | I71: Moritz Wagner | J71: Markelle Fultz | K71: Marquese Chriss
B72: Micah Peavy | C72: Pacome Dadiet | D72: Mike Miles Jr. | E72: Matteo Spagnolo | F72: Marcus Zegarowski | G72: Paul Eboua | H72: Miye Oni | I72: Omari Spellman | J72: Marko Guduric | K72: Marshall Plumlee
B73: Miles Kelly | C73: Pelle Larsson | D73: Mojave King | E73: Max Christie | F73: Matt Coleman III | G73: Paul Reed | H73: Moses Brown | I73: Rawle Alkins | J73: Mathias Lessort | K73: Michael Gbinije
... B101: Yanic Konan Niederhauser | C101: Zyon Pullin | D101: Will Richardson | E101: Ziga Samar | F101: Ziaire Williams | G101: Zeke Nnaji | H101: Zylan Cheatham | I101: Vince Edwards | J101: Zak Irvin | K101: Zhou Qi
